<?xml version="1.0" ?>
<!-- =================================================================================== -->
<!-- |    This document was autogenerated by xacro from /home/kseme/dev_ws/src/robotic_arm/urdf/robot_core.xacro | -->
<!-- |    EDITING THIS FILE BY HAND IS NOT RECOMMENDED                                 | -->
<!-- =================================================================================== -->
<robot name="robotic_arm" xmlns:xacro="http://www.ros.org/wiki/xacro">
  <!-- ****************************************************************************************** -->
  <!-- ***************************************** Base ******************************************* -->
  <!-- ****************************************************************************************** -->
  <material name="grey">
    <color rgba="0.5 0.5 0.5 1"/>
  </material>
  <link name="bottom_base">
    <visual>
      <origin xyz="0 0 0"/>
      <geometry>
        <mesh filename="package://robotic_arm/meshes/bottom_base.stl" scale="0.001 0.001 0.001"/>
      </geometry>
      <material name="grey"/>
    </visual>
    <collision>
      <origin xyz="0 0 0"/>
      <geometry>
        <mesh filename="package://robotic_arm/meshes/bottom_base.stl" scale="0.001 0.001 0.001"/>
      </geometry>
    </collision>
  </link>
  <link name="top_base">
    <visual>
      <origin xyz="0 0 0"/>
      <geometry>
        <mesh filename="package://robotic_arm/meshes/top_base.stl" scale="0.001 0.001 0.001"/>
      </geometry>
      <material name="grey"/>
    </visual>
    <collision>
      <origin xyz="0 0 0"/>
      <geometry>
        <mesh filename="package://robotic_arm/meshes/top_base.stl" scale="0.001 0.001 0.001"/>
      </geometry>
    </collision>
  </link>
  <joint name="base_joint" type="revolute">
    <parent link="bottom_base"/>
    <child link="top_base"/>
    <origin rpy="0 0 0" xyz="0 0 0.04505"/>
    <axis xyz="0 0 1"/>
    <limit effort="100" lower="-3.141592653589793" upper="3.141592653589793" velocity="1"/>
  </joint>
  <!-- ****************************************************************************************** -->
  <!-- *************************************** Shoulder ***************************************** -->
  <!-- ****************************************************************************************** -->
  <link name="shoulder">
    <visual>
      <origin xyz="0 0 0"/>
      <geometry>
        <mesh filename="package://robotic_arm/meshes/shoulder.stl" scale="0.001 0.001 0.001"/>
      </geometry>
    </visual>
    <collision>
      <origin xyz="0 0 0"/>
      <geometry>
        <mesh filename="package://robotic_arm/meshes/shoulder.stl" scale="0.001 0.001 0.001"/>
      </geometry>
    </collision>
  </link>
  <joint name="shoulder_joint" type="revolute">
    <parent link="top_base"/>
    <child link="shoulder"/>
    <origin rpy="0 0 0" xyz="-0.0655 0.13558 0.1998"/>
    <axis xyz="-1 0 0"/>
    <limit effort="100" lower="-2.356194490192345" upper="2.356194490192345" velocity="1"/>
  </joint>
  <!-- ****************************************************************************************** -->
  <!-- *************************************** Elbow ******************************************** -->
  <!-- ****************************************************************************************** -->
  <link name="elbow">
    <visual>
      <origin xyz="0 0 0"/>
      <geometry>
        <mesh filename="package://robotic_arm/meshes/elbow.stl" scale="0.001 0.001 0.001"/>
      </geometry>
    </visual>
    <collision>
      <origin xyz="0 0 0"/>
      <geometry>
        <mesh filename="package://robotic_arm/meshes/elbow.stl" scale="0.001 0.001 0.001"/>
      </geometry>
    </collision>
  </link>
  <joint name="elbow_joint" type="revolute">
    <parent link="shoulder"/>
    <child link="elbow"/>
    <origin rpy="0 0 0" xyz="0.0723 0 0.4131"/>
    <axis xyz="-1 0 0"/>
    <limit effort="100" lower="-3.141592653589793" upper="3.141592653589793" velocity="1"/>
  </joint>
  <!-- ****************************************************************************************** -->
  <!-- *************************************** Wrist ******************************************** -->
  <!-- ****************************************************************************************** -->
  <link name="forearm">
    <visual>
      <origin rpy="-1.5707963267948966 0 0" xyz="0 0 0"/>
      <geometry>
        <mesh filename="package://robotic_arm/meshes/forearm.stl" scale="0.001 0.001 0.001"/>
      </geometry>
    </visual>
    <collision>
      <origin xyz="0 0 0"/>
      <geometry>
        <mesh filename="package://robotic_arm/meshes/forearm.stl" scale="0.001 0.001 0.001"/>
      </geometry>
    </collision>
  </link>
  <joint name="forearm_joint" type="revolute">
    <parent link="elbow"/>
    <child link="forearm"/>
    <origin rpy="0 0 0" xyz="-0.0095 0.110 0.1112"/>
    <axis xyz="0 1 0"/>
    <limit effort="100" lower="-3.141592653589793" upper="3.141592653589793" velocity="1"/>
  </joint>
  <link name="wrist_carrier">
    <visual>
      <origin xyz="0 0 0"/>
      <geometry>
        <mesh filename="package://robotic_arm/meshes/wrist_carrier.stl" scale="0.001 0.001 0.001"/>
      </geometry>
    </visual>
    <collision>
      <origin xyz="0 0 0"/>
      <geometry>
        <mesh filename="package://robotic_arm/meshes/wrist_carrier.stl" scale="0.001 0.001 0.001"/>
      </geometry>
    </collision>
  </link>
  <joint name="wrist_carrier_joint" type="revolute">
    <parent link="forearm"/>
    <child link="wrist_carrier"/>
    <origin rpy="-1.5707963267948966 0 0" xyz="0 0.256 0"/>
    <axis xyz="1 0 0"/>
    <limit effort="100" lower="-2.356194490192345" upper="2.356194490192345" velocity="1"/>
  </joint>
  <link name="wrist_bevel">
    <visual>
      <origin xyz="0 0 0"/>
      <geometry>
        <mesh filename="package://robotic_arm/meshes/wrist_bevel.stl" scale="0.001 0.001 0.001"/>
      </geometry>
    </visual>
    <collision>
      <origin xyz="0 0 0"/>
      <geometry>
        <mesh filename="package://robotic_arm/meshes/wrist_bevel.stl" scale="0.001 0.001 0.001"/>
      </geometry>
    </collision>
  </link>
  <joint name="wrist_bevel_joint" type="revolute">
    <parent link="wrist_carrier"/>
    <child link="wrist_bevel"/>
    <origin rpy="0 0 0" xyz="0 0 0.0399"/>
    <axis xyz="0 0 1"/>
    <limit effort="100" lower="-3.141592653589793" upper="3.141592653589793" velocity="1"/>
  </joint>
  <!-- ****************************************************************************************** -->
  <!-- **************************************** Claw ******************************************** -->
  <!-- ****************************************************************************************** -->
  <link name="claw_base">
    <visual>
      <origin xyz="-0.04 -0.025 0"/>
      <geometry>
        <mesh filename="package://robotic_arm/meshes/claw_base.stl" scale="0.001 0.001 0.001"/>
      </geometry>
    </visual>
    <collision>
      <origin xyz="0 0 0"/>
      <geometry>
        <mesh filename="package://robotic_arm/meshes/claw_base.stl" scale="0.001 0.001 0.001"/>
      </geometry>
    </collision>
  </link>
  <joint name="claw_base_joint" type="fixed">
    <parent link="wrist_bevel"/>
    <child link="claw_base"/>
    <origin rpy="0 0 0" xyz="0 0 0"/>
  </joint>
  <link name="right_claw">
    <visual>
      <origin xyz="0 0 -0.015"/>
      <geometry>
        <mesh filename="package://robotic_arm/meshes/claw_right.stl" scale="0.001 0.001 0.001"/>
      </geometry>
    </visual>
    <collision>
      <origin xyz="0 0 0"/>
      <geometry>
        <mesh filename="package://robotic_arm/meshes/claw_right.stl" scale="0.001 0.001 0.001"/>
      </geometry>
    </collision>
  </link>
  <joint name="right_claw_joint" type="prismatic">
    <parent link="claw_base"/>
    <child link="right_claw"/>
    <origin rpy="1.5707963267948966 0 0" xyz="0 0 0.03"/>
    <axis xyz="1 0 0"/>
    <limit effort="100" lower="0" upper="0.03" velocity="1"/>
  </joint>
  <link name="left_claw">
    <visual>
      <origin xyz="0 0 -0.015"/>
      <geometry>
        <mesh filename="package://robotic_arm/meshes/claw_left.stl" scale="0.001 0.001 0.001"/>
      </geometry>
    </visual>
    <collision>
      <origin xyz="0 0 0"/>
      <geometry>
        <mesh filename="package://robotic_arm/meshes/claw_left.stl" scale="0.001 0.001 0.001"/>
      </geometry>
    </collision>
  </link>
  <joint name="left_claw_joint" type="prismatic">
    <parent link="claw_base"/>
    <child link="left_claw"/>
    <origin rpy="1.5707963267948966 0 0" xyz="0 0 0.03"/>
    <axis xyz="1 0 0"/>
    <limit effort="100" lower="-0.03" upper="0" velocity="1"/>
    <mimic joint="right_claw_joint" multiplier="-1"/>
  </joint>
</robot>
