<?xml version="1.0"?>
<robot xmlns:xacro="http://www.ros.org/wiki/xacro">

    <material name="black">
        <color rgba="0 0 0 1"/>
    </material>

    <material name="grey">
        <color rgba="0.5 0.5 0.5 1"/>
    </material>

    <material name="blue">
        <color rgba="0.2 0.2 1 1"/>
    </material>

    <xacro:property name="scale_factor" value="0.001 0.001 0.001"/>

    <!-- ****************************************************************************************** -->
    <!-- ***************************************** Base ******************************************* -->
    <!-- ****************************************************************************************** -->

    <link name="world">
    </link>

    <link name="bottom_base">
        <visual>
            <origin xyz="0 0 0"/>
            <geometry>
                <mesh filename="package://robotic_arm/meshes/bottom_base.stl" scale="${scale_factor}"/>
            </geometry>
            <material name="grey"/>
        </visual>
        <collision>
            <origin xyz="0 0 0"/>
            <geometry>
                <mesh filename="package://robotic_arm/meshes/bottom_base.stl" scale="${scale_factor}"/>
            </geometry>
        </collision>
    </link>

    <link name="top_base">
        <visual>
            <origin xyz="0 0 0"/>
            <geometry>
                <mesh filename="package://robotic_arm/meshes/top_base.stl" scale="${scale_factor}"/>
            </geometry>
            <material name="blue"/>
        </visual>
        <collision>
            <origin xyz="0 0 0"/>
            <geometry>
                <mesh filename="package://robotic_arm/meshes/top_base.stl" scale="${scale_factor}"/>
            </geometry>
        </collision>
    </link>

    <joint name="base_joint" type="fixed">
        <parent link="world"/>
        <child link="bottom_base"/>
        <origin xyz="0 0 0" rpy="0 0 0"/>
    </joint>

    <joint name="top_base_joint" type="revolute">
        <parent link="bottom_base"/>
        <child link="top_base"/>
        <origin xyz="0 0 0.045" rpy="0 0 0"/>
        <axis xyz="0 0 1"/>
        <limit lower="-${pi}" upper="${pi}" effort="100" velocity="1"/>
    </joint>

    <!-- ****************************************************************************************** -->
    <!-- *************************************** Shoulder ***************************************** -->
    <!-- ****************************************************************************************** -->

    <link name="shoulder">
        <visual>
            <origin xyz="0 0 0"/>
            <geometry>
                <mesh filename="package://robotic_arm/meshes/shoulder.stl" scale="${scale_factor}"/>
            </geometry>
            <material name="grey"/>
        </visual>
        <collision>
            <origin xyz="0 0 0"/>
            <geometry>
                <mesh filename="package://robotic_arm/meshes/shoulder.stl" scale="${scale_factor}"/>
            </geometry>
        </collision>
    </link>

    <joint name="shoulder_joint" type="revolute">
        <parent link="top_base"/>
        <child link="shoulder"/>
        <origin xyz="-0.0655 0.13558 0.1998" rpy="${pi/2} 0 -${pi/2}"/>
        <axis xyz="0 0 1"/>
        <limit lower="-${3*pi/4}" upper="${3*pi/4}" effort="100" velocity="1"/>
    </joint>

    <!-- ****************************************************************************************** -->
    <!-- *************************************** Elbow ******************************************** -->
    <!-- ****************************************************************************************** -->

    <link name="elbow">
        <visual>
            <origin xyz="0 0 0"/>
            <geometry>
                <mesh filename="package://robotic_arm/meshes/elbow.stl" scale="${scale_factor}"/>
            </geometry>
            <material name="blue"/>
        </visual>
        <collision>
            <origin xyz="0 0 0"/>
            <geometry>
                <mesh filename="package://robotic_arm/meshes/elbow.stl" scale="${scale_factor}"/>
            </geometry>
        </collision>
    </link>

    <joint name="elbow_joint" type="revolute">
        <parent link="shoulder"/>
        <child link="elbow"/>
        <origin xyz="0.0068 0.13552 0.61294" rpy="0 0 0"/>
        <axis xyz="0 0 1"/>
        <limit lower="-${pi}" upper="${pi}" effort="100" velocity="1"/>
    </joint>
    

</robot>